<?xml version='1.0' encoding='UTF-8'?>

<sdf version='1.7'>
  <model name="waffle">
  <pose>0 0 0 0 0 0</pose>

    <link name="base_footprint"/>

    <link name="base_link">
      <inertial>
        <pose>-0.064 0 0.048 0 0 0</pose>
        <inertia>
          <ixx>4.2111447e-02</ixx>
          <ixy>0</ixy>
          <ixz>0</ixz>
          <iyy>4.2111447e-02</iyy>
          <iyz>0</iyz>
          <izz>7.5254874e-02</izz>
        </inertia>
        <mass>1.3729096e+00</mass>
      </inertial>
      <collision name="base_collision">
        <pose>-0.064 0 0.048 0 0 0</pose>
        <geometry>
          <box>
            <size>0.265 0.265 0.089</size>
          </box>
        </geometry>
      </collision>
      <visual name="base_visual">
        <pose>-0.064 0 0 0 0 0</pose>
        <geometry>
          <mesh>
            <uri>model://turtlebot3/meshes/waffle_base.dae</uri>
            <scale>0.001 0.001 0.001</scale>
          </mesh>
        </geometry>
        <material>
          <diffuse> 0.921568627 0.925490196 0.941176471 1</diffuse>
          <ambient> 0.921568627 0.925490196 0.941176471 1</ambient>
          <specular>0.921568627 0.925490196 0.941176471 1</specular>
        </material>
      </visual>
    </link>

    <joint name="base_joint" type="fixed">
      <pose>0 0 0.01 0 0 0</pose>
      <parent>base_footprint</parent>
      <child>base_link</child>
    </joint>

    <!-- IMU -->
    <link name="imu_link">
      

         <sensor name="imu_sensor" type="imu">
          <always_on>1</always_on>
          <update_rate>1000</update_rate>
          <visualize>true</visualize>
          <topic>imu</topic>
      </sensor>

     
    </link>
    <joint name="imu_joint" type="fixed">
      <pose>-0.032 0 0.068 0 0 0</pose>
      <parent>base_link</parent>
      <child>imu_link</child>
    </joint>

    <!-- LIDAR -->
    <link name="base_scan">
      <inertial>
        <pose>-0.052 0 0.111 0 0 0</pose>
        <inertia>
          <ixx>0.001</ixx>
          <ixy>0</ixy>
          <ixz>0</ixz>
          <iyy>0.001</iyy>
          <iyz>0</iyz>
          <izz>0.001</izz>
        </inertia>
        <mass>0.114</mass>
      </inertial>
      <collision name="lidar_sensor_collision">
        <pose>-0.052 0 0.111 0 0 0</pose>
        <geometry>
          <cylinder>
            <radius>0.0508</radius>
            <length>0.055</length>
          </cylinder>
        </geometry>
      </collision>
      <visual name="lidar_sensor_visual">
        <pose>-0.064 0 0.121 0 0 0</pose>
        <geometry>
          <mesh>
            <uri>model://turtlebot3/meshes/lds.dae</uri>
            <scale>0.001 0.001 0.001</scale>
          </mesh>
        </geometry>
        <material>
          <diffuse> 0.145098039 0.156862745 0.164705882 1</diffuse>
          <ambient> 0.145098039 0.156862745 0.164705882 1</ambient>
          <specular>0.145098039 0.156862745 0.164705882 1</specular>
        </material>
      </visual>
      <sensor name="gpu_lidar" type="gpu_lidar">
        <pose>-0.064 0 0.121 0 0 0</pose>
        <topic>scan</topic>
        <ignition_frame_id>base_scan</ignition_frame_id>
        <update_rate>5</update_rate>
        <ray>
          <scan>
            <horizontal>
              <samples>360</samples>
              <resolution>1</resolution>
              <min_angle>0</min_angle>
              <max_angle>6.28</max_angle>
            </horizontal>
          </scan>
          <range>
            <min>0.120000</min>
            <max>20.0</max>
            <resolution>0.015000</resolution>
          </range>
          <noise>
            <type>gaussian</type>
            <mean>0.0</mean>
            <stddev>0.01</stddev>
          </noise>
        </ray>
        <always_on>true</always_on>
        <visualize>1</visualize>
      </sensor>
    </link>
    <joint name="lidar_joint" type="fixed">
      <pose>-0.064 0 0.121 0 0 0</pose>
      <parent>base_link</parent>
      <child>base_scan</child>
    </joint>

    <!-- Wheel left -->
    <link name="wheel_left_link">
      <inertial>
        <pose>0.0 0.144 0.023 -1.57 0 0</pose>
        <inertia>
          <ixx>1.1175580e-05</ixx>
          <ixy>-4.2369783e-11</ixy>
          <ixz>-5.9381719e-09</ixz>
          <iyy>1.1192413e-05</iyy>
          <iyz>-1.4400107e-11</iyz>
          <izz>2.0712558e-05</izz>
        </inertia>
        <mass>0.1</mass>
      </inertial>
      <collision name="wheel_left_collision">
        <pose>0.0 0.144 0.023 -1.57 0 0</pose>
        <geometry>
          <cylinder>
            <radius>0.033</radius>
            <length>0.018</length>
          </cylinder>
        </geometry>
        <surface>
          <!-- This friction pamareter don't contain reliable data!! -->
          <friction>
            <ode>
              <mu>100000.0</mu>
              <mu2>100000.0</mu2>
              <fdir1>0 0 0</fdir1>
              <slip1>0.0</slip1>
              <slip2>0.0</slip2>
            </ode>
          </friction>
          <contact>
            <ode>
              <soft_cfm>0</soft_cfm>
              <soft_erp>0.2</soft_erp>
              <kp>1e+5</kp>
              <kd>1</kd>
              <max_vel>0.01</max_vel>
              <min_depth>0.001</min_depth>
            </ode>
          </contact>
        </surface>
      </collision>
      <visual name="wheel_left_visual">
        <pose>0.0 0.144 0.023 0 0 0</pose>
        <geometry>
          <mesh>
            <uri>model://turtlebot3/meshes/tire.dae</uri>
            <scale>0.001 0.001 0.001</scale>
          </mesh>
        </geometry>
        <material>
          <diffuse> 0.145098039 0.156862745 0.164705882 1</diffuse>
          <ambient> 0.145098039 0.156862745 0.164705882 1</ambient>
          <specular>0.145098039 0.156862745 0.164705882 1</specular>
        </material>
      </visual>
    </link>
    <joint name="wheel_left_joint" type="revolute">
      <parent>base_link</parent>
      <child>wheel_left_link</child>
      <pose>0.0 0.144 0.023 -1.57 0 0</pose>
      <axis>
        <xyz>0 0 1</xyz>
      </axis>
    </joint>

    <!-- Wheel right -->
    <link name="wheel_right_link">
      <inertial>
        <pose>0.0 -0.144 0.023 -1.57 0 0</pose>
        <inertia>
          <ixx>1.1175580e-05</ixx>
          <ixy>-4.2369783e-11</ixy>
          <ixz>-5.9381719e-09</ixz>
          <iyy>1.1192413e-05</iyy>
          <iyz>-1.4400107e-11</iyz>
          <izz>2.0712558e-05</izz>
        </inertia>
        <mass>0.1</mass>
      </inertial>
      <collision name="wheel_right_collision">
        <pose>0.0 -0.144 0.023 -1.57 0 0</pose>
        <geometry>
          <cylinder>
            <radius>0.033</radius>
            <length>0.018</length>
          </cylinder>
        </geometry>
        <surface>
          <!-- This friction pamareter don't contain reliable data!! -->
          <friction>
            <ode>
              <mu>100000.0</mu>
              <mu2>100000.0</mu2>
              <fdir1>0 0 0</fdir1>
              <slip1>0.0</slip1>
              <slip2>0.0</slip2>
            </ode>
          </friction>
          <contact>
            <ode>
              <soft_cfm>0</soft_cfm>
              <soft_erp>0.2</soft_erp>
              <kp>1e+5</kp>
              <kd>1</kd>
              <max_vel>0.01</max_vel>
              <min_depth>0.001</min_depth>
            </ode>
          </contact>
        </surface>
      </collision>
      <visual name="wheel_right_visual">
        <pose>0.0 -0.144 0.023 0 0 0</pose>
        <geometry>
          <mesh>
            <uri>model://turtlebot3/meshes/tire.dae</uri>
            <scale>0.001 0.001 0.001</scale>
          </mesh>
        </geometry>
        <material>
          <diffuse> 0.145098039 0.156862745 0.164705882 1</diffuse>
          <ambient> 0.145098039 0.156862745 0.164705882 1</ambient>
          <specular>0.145098039 0.156862745 0.164705882 1</specular>
        </material>
      </visual>
    </link>
    <joint name="wheel_right_joint" type="revolute">
      <parent>base_link</parent>
      <child>wheel_right_link</child>
      <pose>0.0 -0.144 0.023 -1.57 0 0</pose>
      <axis>
        <xyz>0 0 1</xyz>
      </axis>
    </joint>

    <link name='caster_back_right_link'>
      <pose>-0.177 -0.064 -0.004 -1.57 0 0</pose>
      <inertial>
        <mass>0.001</mass>
        <inertia>
          <ixx>0.00001</ixx>
          <ixy>0.000</ixy>
          <ixz>0.000</ixz>
          <iyy>0.00001</iyy>
          <iyz>0.000</iyz>
          <izz>0.00001</izz>
        </inertia>
      </inertial>
      <collision name='collision'>
        <geometry>
          <sphere>
            <radius>0.005000</radius>
          </sphere>
        </geometry>
        <surface>
          <contact>
            <ode>
              <soft_cfm>0</soft_cfm>
              <soft_erp>0.2</soft_erp>
              <kp>1e+5</kp>
              <kd>1</kd>
              <max_vel>0.01</max_vel>
              <min_depth>0.001</min_depth>
            </ode>
          </contact>
        </surface>
      </collision>
    </link>
    <joint name='caster_back_right_joint' type='ball'>
      <parent>base_link</parent>
      <child>caster_back_right_link</child>
    </joint>

    <link name='caster_back_left_link'>
      <pose>-0.177 0.064 -0.004 -1.57 0 0</pose>
      <inertial>
        <mass>0.001</mass>
        <inertia>
          <ixx>0.00001</ixx>
          <ixy>0.000</ixy>
          <ixz>0.000</ixz>
          <iyy>0.00001</iyy>
          <iyz>0.000</iyz>
          <izz>0.00001</izz>
        </inertia>
      </inertial>
      <collision name='collision'>
        <geometry>
          <sphere>
            <radius>0.005000</radius>
          </sphere>
        </geometry>
        <surface>
          <contact>
            <ode>
              <soft_cfm>0</soft_cfm>
              <soft_erp>0.2</soft_erp>
              <kp>1e+5</kp>
              <kd>1</kd>
              <max_vel>0.01</max_vel>
              <min_depth>0.001</min_depth>
            </ode>
          </contact>
        </surface>
      </collision>
    </link>
    <joint name='caster_back_left_joint' type='ball'>
      <parent>base_link</parent>
      <child>caster_back_left_link</child>
    </joint>


     <!-- Left camera link -->
    <link name="left_camera_link">
      <pose>-0.18 0.18 0.206749999999999999 3.14 3.14 0</pose>
     
     <sensor name="left_camera" type="camera">
        <pose>0 0 0.248750000000000001 0 0 0</pose>
        <camera>
          <horizontal_fov>1.4</horizontal_fov>
           <image>
            <width>640</width>
            <height>480</height>
          </image>
          <clip>
            <near>0.2</near>
            <far>20.0</far>
          </clip>
        </camera>
         <frame_id>left_camera_link</frame_id>
        <always_on>1</always_on>
        <update_rate>15</update_rate>
        <visualize>true</visualize>
        <topic>gazebo/stereo_camera/right</topic>
      </sensor>
      <inertial>
        <mass>0.001</mass>
        <inertia>
          <ixx>0.001</ixx>
          <ixy>0</ixy>
          <ixz>0</ixz>
          <iyy>0.001</iyy>
          <iyz>0</iyz>
          <izz>0.001</izz>
        </inertia>
      </inertial>
    </link>

    <!-- Attach left_camera_link to base_link -->
    <joint name="left_camera_joint" type="fixed">
      <!-- <pose>-0.15 0.18 0.3 0 1.5707963267948966 0</pose> -->
      <parent>base_link</parent>
      <child>left_camera_link</child>
    </joint>

    <!-- Right camera link -->
    <link name="right_camera_link">
      <pose>-0.18 -0.18 0.206749999999999999 3.14 3.14 0</pose>
     
       <sensor name="right_camera" type="camera">
        <pose>0 0 0.248750000000000001 0 0 0</pose>
        <camera>
          <horizontal_fov>1.4</horizontal_fov>
          <image>
            <width>640</width>
            <height>480</height>
          </image>
          <clip>
            <near>0.2</near>
            <far>20.0</far>
          </clip>
        </camera>
        <always_on>1</always_on>
        <update_rate>15</update_rate>
        <visualize>true</visualize>
          <frame_id>right_camera_link</frame_id>
        <topic>gazebo/stereo_camera/left</topic>
      </sensor>
      <inertial>
        <mass>0.001</mass>
        <inertia>
          <ixx>0.001</ixx>
          <ixy>0</ixy>
          <ixz>0</ixz>
          <iyy>0.001</iyy>
          <iyz>0</iyz>
          <izz>0.001</izz>
        </inertia>
      </inertial>
    </link>

    <!-- Attach right_camera_link to camera_link -->
    <joint name="right_camera_joint" type="fixed">
      <!-- <pose>-0.15 -0.18 0.3 0 1.5707963267948966 0</pose> -->
      <parent>base_link</parent>
      <child>right_camera_link</child>
    </joint>


    <!-- Global odometer -->
    <plugin
      filename="ignition-gazebo-odometry-publisher-system"
      name="ignition::gazebo::systems::OdometryPublisher">
      <odom_publish_frequency>50</odom_publish_frequency>
      <odom_topic>/odom</odom_topic>
      <odom_frame>odom</odom_frame>
      <robot_base_frame>base_footprint</robot_base_frame>
      <tf_topic>/odom/tf</tf_topic>
    </plugin>

    <!-- Differential drive -->
    <plugin filename="libignition-gazebo-diff-drive-system.so" 
      name="ignition::gazebo::systems::DiffDrive">
      <left_joint>wheel_left_joint</left_joint>
      <right_joint>wheel_right_joint</right_joint>
      <wheel_separation>0.287</wheel_separation>
      <wheel_radius>0.033</wheel_radius>
      <topic>cmd_vel</topic>
    </plugin>

    <!-- Joint state publisher -->
    <plugin filename="libignition-gazebo-joint-state-publisher-system.so" 
      name="ignition::gazebo::systems::JointStatePublisher">
      <topic>joint_states</topic>
    </plugin>

  </model>
</sdf>